[2023-06-15T07:45:01.256+0000] {taskinstance.py:1087} INFO - Dependencies all met for <TaskInstance: add_entry_dag.create_table_task manual__2023-06-15T07:45:00.583369+00:00 [queued]>
[2023-06-15T07:45:01.276+0000] {taskinstance.py:1087} INFO - Dependencies all met for <TaskInstance: add_entry_dag.create_table_task manual__2023-06-15T07:45:00.583369+00:00 [queued]>
[2023-06-15T07:45:01.278+0000] {taskinstance.py:1283} INFO - 
--------------------------------------------------------------------------------
[2023-06-15T07:45:01.279+0000] {taskinstance.py:1284} INFO - Starting attempt 1 of 1
[2023-06-15T07:45:01.280+0000] {taskinstance.py:1285} INFO - 
--------------------------------------------------------------------------------
[2023-06-15T07:45:01.297+0000] {taskinstance.py:1304} INFO - Executing <Task(PythonOperator): create_table_task> on 2023-06-15 07:45:00.583369+00:00
[2023-06-15T07:45:01.309+0000] {standard_task_runner.py:55} INFO - Started process 212 to run task
[2023-06-15T07:45:01.322+0000] {standard_task_runner.py:82} INFO - Running: ['***', 'tasks', 'run', 'add_entry_dag', 'create_table_task', 'manual__2023-06-15T07:45:00.583369+00:00', '--job-id', '4', '--raw', '--subdir', 'DAGS_FOLDER/postgres_dag.py', '--cfg-path', '/tmp/tmpibgosixy']
[2023-06-15T07:45:01.330+0000] {standard_task_runner.py:83} INFO - Job 4: Subtask create_table_task
[2023-06-15T07:45:01.451+0000] {task_command.py:389} INFO - Running <TaskInstance: add_entry_dag.create_table_task manual__2023-06-15T07:45:00.583369+00:00 [running]> on host 0413488a6cc2
[2023-06-15T07:45:01.527+0000] {taskinstance.py:1513} INFO - Exporting the following env vars:
AIRFLOW_CTX_DAG_OWNER=***
AIRFLOW_CTX_DAG_ID=add_entry_dag
AIRFLOW_CTX_TASK_ID=create_table_task
AIRFLOW_CTX_EXECUTION_DATE=2023-06-15T07:45:00.583369+00:00
AIRFLOW_CTX_TRY_NUMBER=1
AIRFLOW_CTX_DAG_RUN_ID=manual__2023-06-15T07:45:00.583369+00:00
[2023-06-15T07:45:01.551+0000] {taskinstance.py:1772} ERROR - Task failed with exception
Traceback (most recent call last):
  File "/home/airflow/.local/lib/python3.7/site-packages/airflow/operators/python.py", line 175, in execute
    return_value = self.execute_callable()
  File "/home/airflow/.local/lib/python3.7/site-packages/airflow/operators/python.py", line 192, in execute_callable
    return self.python_callable(*self.op_args, **self.op_kwargs)
  File "/opt/airflow/dags/postgres_dag.py", line 14, in create_table_if_not_exists
    postgres_hook.run(create_table_query)
  File "/home/airflow/.local/lib/python3.7/site-packages/airflow/providers/common/sql/hooks/sql.py", line 331, in run
    with closing(self.get_conn()) as conn:
  File "/home/airflow/.local/lib/python3.7/site-packages/airflow/providers/postgres/hooks/postgres.py", line 117, in get_conn
    conn = deepcopy(self.connection or self.get_connection(conn_id))
  File "/home/airflow/.local/lib/python3.7/site-packages/airflow/hooks/base.py", line 72, in get_connection
    conn = Connection.get_connection_from_secrets(conn_id)
  File "/home/airflow/.local/lib/python3.7/site-packages/airflow/models/connection.py", line 432, in get_connection_from_secrets
    raise AirflowNotFoundException(f"The conn_id `{conn_id}` isn't defined")
airflow.exceptions.AirflowNotFoundException: The conn_id `postgres_connection` isn't defined
[2023-06-15T07:45:01.560+0000] {taskinstance.py:1327} INFO - Marking task as FAILED. dag_id=add_entry_dag, task_id=create_table_task, execution_date=20230615T074500, start_date=20230615T074501, end_date=20230615T074501
[2023-06-15T07:45:01.573+0000] {standard_task_runner.py:105} ERROR - Failed to execute job 4 for task create_table_task (The conn_id `postgres_connection` isn't defined; 212)
[2023-06-15T07:45:01.615+0000] {local_task_job.py:159} INFO - Task exited with return code 1
[2023-06-15T07:45:01.645+0000] {taskinstance.py:2582} INFO - 0 downstream tasks scheduled from follow-on schedule check
